Traceback (most recent call last):
  File "/home/wejdene/polytechnique/blockcompass/env/lib/python3.6/site-packages/pymongo/mongo_client.py", line 1458, in _retry_internal
    server = self._select_server(writable_server_selector, session)
  File "/home/wejdene/polytechnique/blockcompass/env/lib/python3.6/site-packages/pymongo/mongo_client.py", line 1346, in _select_server
    server = topology.select_server(server_selector)
  File "/home/wejdene/polytechnique/blockcompass/env/lib/python3.6/site-packages/pymongo/topology.py", line 246, in select_server
    address))
  File "/home/wejdene/polytechnique/blockcompass/env/lib/python3.6/site-packages/pymongo/topology.py", line 203, in select_servers
    selector, server_timeout, address)
  File "/home/wejdene/polytechnique/blockcompass/env/lib/python3.6/site-packages/pymongo/topology.py", line 220, in _select_servers_loop
    (self._error_message(selector), timeout, self.description))
pymongo.errors.ServerSelectionTimeoutError: 132.207.227.22:27013: [Errno 111] Connection refused,132.207.227.22:27012: [Errno 111] Connection refused,132.207.227.22:27011: [Errno 111] Connection refused, Timeout: 30s, Topology Description: <TopologyDescription id: 621d5176e23e8d7f6f81b63f, topology_type: ReplicaSetNoPrimary, servers: [<ServerDescription ('132.207.227.22', 27011) server_type: Unknown, rtt: None, error=AutoReconnect('132.207.227.22:27011: [Errno 111] Connection refused',)>, <ServerDescription ('132.207.227.22', 27012) server_type: Unknown, rtt: None, error=AutoReconnect('132.207.227.22:27012: [Errno 111] Connection refused',)>, <ServerDescription ('132.207.227.22', 27013) server_type: Unknown, rtt: None, error=AutoReconnect('132.207.227.22:27013: [Errno 111] Connection refused',)>]>

During handling of the above exception, another exception occurred:

Traceback (most recent call last):
  File "main.py", line 26, in <module>
    main()
  File "main.py", line 16, in main
    docker_monitor.get_measurements()
  File "/home/wejdene/polytechnique/blockcompass-v2/blockcompass/monitor/dockerMonitoring.py", line 98, in get_measurements
    self.database_insertion(data)
  File "/home/wejdene/polytechnique/blockcompass-v2/blockcompass/monitor/monitoring.py", line 9, in database_insertion
    self.database.inset_to_database(data)
  File "/home/wejdene/polytechnique/blockcompass-v2/blockcompass/monitor/mongoDB.py", line 20, in inset_to_database
    self.collection.insert_one(item)
  File "/home/wejdene/polytechnique/blockcompass/env/lib/python3.6/site-packages/pymongo/collection.py", line 708, in insert_one
    session=session),
  File "/home/wejdene/polytechnique/blockcompass/env/lib/python3.6/site-packages/pymongo/collection.py", line 622, in _insert
    bypass_doc_val, session)
  File "/home/wejdene/polytechnique/blockcompass/env/lib/python3.6/site-packages/pymongo/collection.py", line 610, in _insert_one
    acknowledged, _insert_command, session)
  File "/home/wejdene/polytechnique/blockcompass/env/lib/python3.6/site-packages/pymongo/mongo_client.py", line 1552, in _retryable_write
    return self._retry_with_session(retryable, func, s, None)
  File "/home/wejdene/polytechnique/blockcompass/env/lib/python3.6/site-packages/pymongo/mongo_client.py", line 1438, in _retry_with_session
    return self._retry_internal(retryable, func, session, bulk)
  File "/home/wejdene/polytechnique/blockcompass/env/lib/python3.6/site-packages/pymongo/mongo_client.py", line 1476, in _retry_internal
    raise last_error
  File "/home/wejdene/polytechnique/blockcompass/env/lib/python3.6/site-packages/pymongo/mongo_client.py", line 1462, in _retry_internal
    with self._get_socket(server, session) as sock_info:
  File "/usr/lib/python3.6/contextlib.py", line 81, in __enter__
    return next(self.gen)
  File "/home/wejdene/polytechnique/blockcompass/env/lib/python3.6/site-packages/pymongo/mongo_client.py", line 1309, in _get_socket
    self.__all_credentials, handler=err_handler) as sock_info:
  File "/usr/lib/python3.6/contextlib.py", line 81, in __enter__
    return next(self.gen)
  File "/home/wejdene/polytechnique/blockcompass/env/lib/python3.6/site-packages/pymongo/pool.py", line 1331, in get_socket
    sock_info = self._get_socket(all_credentials)
  File "/home/wejdene/polytechnique/blockcompass/env/lib/python3.6/site-packages/pymongo/pool.py", line 1397, in _get_socket
    sock_info = self.connect(all_credentials)
  File "/home/wejdene/polytechnique/blockcompass/env/lib/python3.6/site-packages/pymongo/pool.py", line 1287, in connect
    _raise_connection_failure(self.address, error)
  File "/home/wejdene/polytechnique/blockcompass/env/lib/python3.6/site-packages/pymongo/pool.py", line 247, in _raise_connection_failure
    raise AutoReconnect(msg)
pymongo.errors.AutoReconnect: 132.207.227.22:27011: [Errno 111] Connection refused
